Workbook

Sheet PETUNJUK
A1: APLIKASI ANALISIS BUTIR SOAL PILIHAN GANDA
A2: =UPPER(NAMA_MADRASAH)&" | TAHUN PELAJARAN "&TAHUN_AJAR -> MTSN 3 SUBANG | TAHUN PELAJARAN 2025-2026
A4: A. CARA PENGGUNAAN
A5: 1 | B5: Buka sheet IDENTITAS: isi mata pelajaran, kelas, nama guru, kepala madrasah; sesuaikan KKM dan parameter bila perlu.
A6: 2 | B6: Buka sheet KUNCI: isi kunci jawaban (A/B/C/D) tiap nomor. Maksimal 40 butir; nomor yang dikosongkan tidak dianalisis.
A7: 3 | B7: Buka sheet JAWABAN: isi nama siswa dan pilihan jawaban tiap butir (A/B/C/D). Maksimal 50 siswa; kosongkan sel bila siswa tidak menjawab (dihitung salah).
A8: 4 | B8: Data yang ada saat ini ADALAH DATA CONTOH (32 siswa fiktif dan kunci acak). Hapus isian di sheet KUNCI (B6:B45) dan JAWABAN (B6:AR55) sebelum memasukkan data asli.
A9: 5 | B9: Sheet SKOR, NILAI, ANALISIS, PENGECOH, dan REKAP terisi otomatis oleh rumus - jangan diketik ulang.
A10: 6 | B10: Hasil dibaca di REKAP (ringkasan, grafik, kesimpulan, tanda tangan) dan ANALISIS (per butir). Semua sheet hasil sudah diatur untuk dicetak landscape.
A12: B. LEGENDA
B13: Kuning, huruf biru: sel isian (boleh diubah)
B14: Putih, huruf hitam: rumus otomatis (jangan diubah)
A16: C. RUMUS DAN KRITERIA
A17: Aspek | B17: Rumus | C17: Kriteria
A18: Tingkat kesukaran | B18: p = B / N (B = jumlah penjawab benar, N = jumlah peserta) | C18: Sukar: p <= 0,30; Sedang: 0,30 < p <= 0,70; Mudah: p > 0,70
A19: Daya pembeda | B19: D = (BA - BB) / n (kelompok atas dan bawah masing-masing 27% peserta, diurutkan menurut skor total) | C19: D < 0 sangat jelek; 0 - 0,20 jelek; 0,21 - 0,40 cukup; 0,41 - 0,70 baik; > 0,70 baik sekali
A20: Validitas butir | B20: r pbis = (Mp - Mt) / SDt x akar(p/q) (Mp = rata-rata skor total penjawab benar; Mt, SDt = rata-rata & SD skor total) | C20: Valid bila r hitung > r tabel (alpha 5%, db = N - 2). Bila semua/tidak ada yang menjawab benar, r tidak dapat dihitung dan butir dianggap tidak valid.
A21: Reliabilitas tes | B21: KR-20: r11 = k/(k-1) x (1 - Sum(pq) / Varians skor total) | C21: >= 0,80 sangat tinggi; 0,60 - 0,79 tinggi; 0,40 - 0,59 cukup; 0,20 - 0,39 rendah; < 0,20 sangat rendah
A22: Efektivitas pengecoh | B22: Persentase peserta yang memilih tiap opsi (juga jumlah di kelompok atas & bawah) | C22: Pengecoh berfungsi bila dipilih >= 5% peserta
A23: Rekomendasi | B23: Tiga syarat: (1) valid, (2) daya pembeda > 0,20, (3) tingkat kesukaran sedang | C23: 3 syarat terpenuhi = Diterima; 2 syarat = Direvisi; 1 atau 0 syarat, atau D negatif = Diganti/Dibuang
A25: D. CATATAN
A26: - | B26: Setiap jawaban benar diberi skor 1 dan salah/kosong 0. Nilai = skor total / jumlah butir x 100.
A27: - | B27: Angka kriteria di atas adalah nilai awal dan mengikuti parameter di sheet IDENTITAS bila Anda mengubahnya. Kriteria mengacu pada Arikunto, Dasar-Dasar Evaluasi Pendidikan.
A28: - | B28: Korelasi butir-total tidak dikoreksi (butir ikut dihitung dalam skor total). Untuk hasil yang stabil, disarankan jumlah peserta minimal 30 siswa.
A29: - | B29: Kolom bantu abu-abu di ANALISIS (T:V) dan SKOR (kunci urut) dipakai oleh rumus; jangan dihapus.

Sheet KUNCI
A1: KUNCI JAWABAN
A2: =UPPER(NAMA_MADRASAH)&" | TAHUN PELAJARAN "&TAHUN_AJAR -> MTSN 3 SUBANG | TAHUN PELAJARAN 2025-2026
A3: =MAPEL&" | Kelas "&KELAS&" | Semester "&SEMESTER&" | "&JENIS_TES -> Bahasa Indonesia | Kelas IX G | Semester Ganjil | Penilaian Akhir Semester
A4: DATA CONTOH - ganti dengan kunci jawaban asli. Kosongkan nomor yang tidak dipakai.
A5: No | B5: Kunci Jawaban (A/B/C/D) | C5: Materi / Indikator Soal (opsional)
A6: 1 | B6: A
A7: 2 | B7: D
A8: 3 | B8: B
A9: 4 | B9: A
A10: 5 | B10: C
A11: 6 | B11: C
A12: 7 | B12: B
A13: 8 | B13: D
A14: 9 | B14: D
A15: 10 | B15: C
A16: 11 | B16: C
A17: 12 | B17: C
... A45: 40 | B45: C

Sheet IDENTITAS
A1: IDENTITAS & PARAMETER ANALISIS
A2: Sel berwarna kuning dengan huruf biru = isian yang boleh diubah.
A4: A. IDENTITAS
A5: Nama Madrasah | B5: MTsN 3 Subang
A6: Tempat (untuk tanda tangan) | B6: Subang
A7: Tahun Pelajaran | B7: 2025-2026
A8: Semester | B8: Ganjil | C8: Pilih Ganjil / Genap (asumsi awal: Ganjil)
A9: Mata Pelajaran | B9: Bahasa Indonesia | C9: Wajib diisi
A10: Kelas | B10: IX G | C10: Wajib diisi
A11: Jenis Penilaian | B11: Penilaian Akhir Semester | C11: Ubah sesuai ulangan yang dianalisis (PH/PTS/PAS/dll.)
A12: Bentuk Soal | B12: Pilihan Ganda (opsi A-D) | C12: Aplikasi ini untuk pilihan ganda 4 opsi
A13: Guru Mata Pelajaran | B13: Enok Demiyati, S.Pd.
A14: NIP Guru | B14: 196906252005012003
A15: Kepala Madrasah | B15: Rosih, S.Ag
A16: NIP Kepala Madrasah | B16: 197010281994032001
A17: Tanggal Analisis | B17: Senin, 01 Desember 2025 | C17: Ditulis bebas, mis. 15 Januari 2025
A19: B. PARAMETER ANALISIS
A20: KKM / KKTP | B20: 75 | C20: Asumsi awal 75 - sesuaikan dengan KKM/KKTP madrasah
A21: Persentase kelompok atas & bawah | B21: 0.27 | C21: Kelley: 27% peserta tertinggi dan 27% terendah
A22: Taraf signifikansi (alpha) uji validitas | B22: 0.05 | C22: r tabel dihitung dari distribusi t (dua arah), db = N - 2
A23: Soal SUKAR jika p <= | B23: 0.3 | C23: Mengacu Arikunto, Dasar-Dasar Evaluasi Pendidikan
A24: Soal MUDAH jika p > | B24: 0.7 | C24: Di antara kedua batas = SEDANG
A25: Daya pembeda JELEK jika D <= | B25: 0.2 | C25: D < 0 = sangat jelek
A26: Daya pembeda CUKUP jika D <= | B26: 0.4
A27: Daya pembeda BAIK jika D <= | B27: 0.7 | C27: Di atasnya = baik sekali
A28: Pengecoh berfungsi jika dipilih >= | B28: 0.05 | C28: Persentase dari seluruh peserta

Sheet JAWABAN
A1: DATA JAWABAN SISWA
A2: =UPPER(NAMA_MADRASAH)&" | TAHUN PELAJARAN "&TAHUN_AJAR -> MTSN 3 SUBANG | TAHUN PELAJARAN 2025-2026
A3: =MAPEL&" | Kelas "&KELAS&" | Semester "&SEMESTER&" | "&JENIS_TES -> Bahasa Indonesia | Kelas IX G | Semester Ganjil | Penilaian Akhir Semester
A4: DATA CONTOH (32 siswa fiktif) - hapus isi B6:AR55 lalu isi dengan data asli. Kosongkan sel jika siswa tidak menjawab.
A5: No | B5: Nama Siswa | C5: Kelas | D5: NISN | E5: 1 | F5: 2 | G5: 3 | H5: 4 | I5: 5 | J5: 6 | K5: 7 | L5: 8 | M5: 9 | N5: 10 | O5: 11 | P5: 12 | Q5: 13 | R5: 14 | S5: 15 | T5: 16 | U5: 17 | V5: 18 | W5: 19 | X5: 20 | Y5: 21 | Z5: 22 | AA5: 23 | AB5: 24 | AC5: 25 | AD5: 26 | AE5: 27 | AF5: 28 | AG5: 29 | AH5: 30 | AI5: 31 | AJ5: 32 | AK5: 33 | AL5: 34 | AM5: 35 | AN5: 36 | AO5: 37 | AP5: 38 | AQ5: 39 | AR5: 40
A6: 1 | B6: SISWA 01 | C6: =KELAS -> IX G | D6: 0123031 | E6: A | F6: C | G6: B | H6: C | I6: C | J6: D | K6: D | L6: D | M6: C | N6: B | P6: B | Q6: D | R6: D | S6: C | T6: B | U6: C | V6: C | W6: A | X6: C | Y6: D | Z6: D | AA6: C | AB6: A | AC6: C | AD6: C | AE6: D | AF6: D | AG6: D | AH6: D | AJ6: D | AK6: A | AL6: B | AM6: C | AN6: B | AO6: C | AP6: B | AQ6: B | AR6: A
A7: 2 | B7: SISWA 02 | C7: =KELAS -> IX G | D7: 0123030 | E7: B | F7: D | G7: D | H7: A | I7: C | J7: C | K7: B | L7: D | M7: D | N7: B | O7: C | P7: C | Q7: D | R7: A | S7: B | T7: C | U7: C | V7: A | W7: C | X7: B | Y7: D | Z7: D | AA7: A | AB7: C | AC7: D | AE7: A | AF7: C | AG7: D | AH7: D | AJ7: B | AK7: D | AL7: B | AM7: A | AN7: B | AO7: B | AP7: D | AQ7: D | AR7: C
A8: 3 | B8: SISWA 03 | C8: =KELAS -> IX G | D8: 0123029 | E8: B | F8: B | G8: C | H8: A | I8: B | J8: B | K8: C | L8: D | M8: D | N8: B | O8: B | P8: C | Q8: D | R8: A | S8: D | T8: C | U8: D | V8: B | W8: C | X8: D | Y8: B | Z8: D | AA8: A | AB8: C | AC8: D | AD8: B | AE8: C | AF8: B | AG8: C | AH8: C | AI8: B | AJ8: C | AL8: B | AM8: A | AN8: B | AO8: C | AP8: A | AQ8: D | AR8: A
A9: 4 | B9: SISWA 04 | C9: =KELAS -> IX G | D9: 0123028 | E9: C | F9: C | G9: B | H9: A | I9: B | J9: B | K9: B | L9: D | M9: D | N9: C | O9: C | P9: B | Q9: D | R9: D | S9: B | T9: D | U9: C | V9: A | X9: A | Y9: D | Z9: D | AA9: A | AB9: D | AC9: B | AD9: D | AE9: B | AF9: D | AG9: A | AH9: D | AI9: B | AJ9: B | AK9: B | AL9: B | AM9: C | AN9: D | AO9: B | AP9: C | AQ9: C | AR9: C
A10: 5 | B10: SISWA 05 | C10: =KELAS -> IX G | D10: 0123027 | E10: A | F10: D | G10: B | I10: C | J10: B | K10: C | L10: D | M10: D | N10: C | O10: C | P10: C | Q10: D | R10: A | S10: B | T10: C | U10: C | V10: A | W10: C | X10: B | Y10: D | Z10: D | AA10: A | AB10: C | AC10: D | AD10: C | AE10: C | AF10: B | AG10: D | AH10: D | AI10: B | AJ10: B | AK10: D | AL10: B | AM10: A | AN10: B | AO10: B | AP10: B | AQ10: B | AR10: C
A11: 6 | B11: SISWA 06 | C11: =KELAS -> IX G | D11: 0123026 | E11: C | F11: C | G11: C | H11: A | J11: C | K11: B | L11: D | M11: D | N11: C | O11: C | P11: D | Q11: D | R11: A | S11: B | T11: D | U11: A | V11: A | W11: C | X11: B | Y11: D | Z11: D | AA11: A | AB11: C | AC11: A | AD11: C | AE11: C | AF11: C | AG11: D | AH11: D | AI11: B | AJ11: B | AK11: B | AL11: D | AM11: A | AN11: B | AO11: B | AP11: B | AQ11: D | AR11: D
A12: 7 | B12: SISWA 07 | C12: =KELAS -> IX G | D12: 0123025 | E12: A | F12: A | G12: B | H12: A | I12: D | J12: C | K12: B | L12: D | M12: D | N12: C | O12: D | P12: D | Q12: D | R12: D | S12: C | T12: D | U12: B | V12: D | W12: C | X12: A | Y12: D | Z12: C | AA12: A | AB12: C | AC12: D | AD12: A | AE12: C | AF12: D | AG12: C | AH12: D | AI12: D | AJ12: B | AK12: D | AL12: D | AM12: A | AN12: B | AO12: C | AP12: B | AQ12: D | AR12: C
A13: 8 | B13: SISWA 08 | C13: =KELAS -> IX G | D13: 0123024 | F13: B | G13: C | H13: B | I13: C | K13: B | L13: D | M13: A | N13: A | O13: B | P13: A | Q13: D | R13: A | S13: D | T13: B | U13: C | V13: A | W13: C | X13: B | Y13: D | Z13: C | AA13: C | AB13: A | AC13: D | AD13: D | AE13: B | AF13: B | AG13: B | AH13: D | AI13: D | AJ13: D | AK13: D | AL13: D | AM13: A | AN13: B | AO13: B | AP13: C | AQ13: A | AR13: C
A14: 9 | B14: SISWA 09 | C14: =KELAS -> IX G | D14: 0123023 | E14: A | F14: D | G14: B | H14: D | I14: C | K14: C | L14: A | M14: B | N14: B | O14: A | P14: C | Q14: D | R14: D | S14: B | T14: A | U14: B | W14: C | X14: B | Y14: A | Z14: C | AA14: A | AB14: B | AC14: D | AD14: B | AE14: A | AG14: D | AH14: D | AI14: B | AJ14: B | AK14: D | AL14: D | AM14: D | AN14: D | AO14: B | AP14: B | AQ14: A | AR14: C
A15: 10 | B15: SISWA 10 | C15: =KELAS -> IX G | D15: 0123022 | E15: A | F15: D | G15: B | H15: A | I15: C | J15: B | K15: D | L15: C | M15: A | N15: D | O15: D | P15: C | Q15: D | R15: C | S15: C | T15: A | U15: B | V15: D | W15: C | X15: B | Y15: C | Z15: C | AA15: B | AB15: C | AC15: D | AD15: A | AE15: B | AF15: D | AG15: A | AH15: D | AI15: A | AJ15: B | AK15: D | AL15: B | AM15: A | AN15: B | AO15: A | AP15: B | AQ15: D | AR15: C
A16: 11 | B16: SISWA 11 | C16: =KELAS -> IX G | D16: 0123021 | E16: A | F16: D | G16: D | H16: A | I16: A | J16: C | K16: B | L16: D | M16: A | N16: C | O16: D | P16: C | Q16: D | R16: A | S16: B | T16: C | U16: D | V16: A | W16: D | X16: B | Y16: D | Z16: D | AA16: A | AB16: C | AC16: D | AD16: C | AE16: C | AF16: B | AG16: D | AI16: A | AJ16: A | AK16: D | AL16: B | AM16: A | AN16: B | AO16: B | AP16: D | AQ16: D | AR16: C
A17: 12 | B17: SISWA 12 | C17: =KELAS -> IX G | D17: 0123020 | E17: A | F17: D | G17: A | H17: A | I17: C | J17: C | L17: D | M17: B | N17: C | O17: C | P17: C | Q17: A | R17: A | S17: D | T17: B | V17: C | W17: A | X17: D | Y17: D | Z17: A | AA17: A | AB17: C | AC17: B | AD17: C | AF17: B | AG17: B | AH17: A | AI17: B | AJ17: B | AK17: D | AL17: B | AM17: A | AN17: B | AO17: A | AP17: B | AQ17: D | AR17: C
A18: 13 | B18: SISWA 13 | C18: =KELAS -> IX G | D18: 0123019 | E18: A | F18: D | G18: D | H18: A | I18: C | J18: C | K18: B | L18: D | N18: A | O18: C | P18: C | Q18: D | R18: B | S18: B | T18: C | U18: D | V18: A | W18: C | X18: B | Y18: D | Z18: D | AB18: C | AC18: D | AD18: C | AE18: C | AF18: C | AG18: D | AH18: D | AI18: C | AJ18: B | AK18: D | AL18: B | AM18: A | AN18: B | AO18: B | AP18: B | AQ18: A | AR18: C
A19: 14 | B19: SISWA 14 | C19: =KELAS -> IX G | D19: 0123018 | E19: C | F19: D | H19: C | I19: D | K19: D | L19: C | M19: C | N19: C | O19: D | P19: B | Q19: D | R19: B | S19: A | T19: C | U19: B | V19: D | W19: D | X19: B | Y19: D | Z19: D | AA19: B | AB19: A | AC19: C | AD19: C | AE19: C | AF19: B | AG19: C | AH19: A | AI19: B | AJ19: B | AK19: D | AL19: A | AM19: B | AN19: D | AO19: D | AQ19: D | AR19: D
A20: 15 | B20: SISWA 15 | C20: =KELAS -> IX G | D20: 0123017 | E20: A | F20: D | G20: B | H20: A | I20: C | J20: D | K20: B | L20: D | M20: D | N20: B | O20: C | Q20: B | R20: C | S20: B | T20: B | U20: C | V20: C | W20: D | X20: A | Y20: C | Z20: D | AA20: A | AB20: C | AC20: C | AD20: D | AE20: C | AF20: D | AG20: D | AH20: A | AI20: B | AJ20: B | AK20: A | AL20: B | AM20: A | AN20: B | AO20: B | AP20: C | AQ20: A | AR20: C
A21: 16 | B21: SISWA 16 | C21: =KELAS -> IX G | D21: 0123016 | E21: A | F21: A | G21: C | H21: A | I21: A | J21: C | K21: B | L21: D | M21: A | N21: C | O21: C | P21: C | R21: A | S21: B | T21: C | U21: D | V21: A | W21: C | X21: B | Y21: D | Z21: D | AA21: A | AB21: C | AC21: D | AD21: C | AE21: A | AF21: C | AG21: C | AH21: D | AI21: B | AJ21: B | AK21: D | AL21: B | AM21: A | AN21: B | AO21: D | AP21: C | AQ21: B | AR21: C
A22: 17 | B22: SISWA 17 | C22: =KELAS -> IX G | D22: 0123015 | E22: B | F22: D | G22: B | H22: A | I22: C | J22: C | K22: B | L22: D | M22: D | N22: C | O22: C | P22: C | R22: A | S22: B | T22: C | U22: B | V22: A | W22: C | X22: B | Y22: A | Z22: C | AA22: A | AB22: C | AC22: A | AD22: A | AE22: C | AF22: C | AG22: D | AH22: D | AI22: B | AJ22: B | AK22: B | AL22: B | AM22: A | AN22: A | AO22: B | AP22: B | AQ22: D | AR22: C
A23: 18 | B23: SISWA 18 | C23: =KELAS -> IX G | D23: 0123014 | E23: B | F23: D | G23: B | H23: A | I23: C | J23: C | K23: B | L23: D | M23: B | N23: C | O23: C | P23: C | Q23: A | R23: A | S23: B | T23: C | U23: C | V23: D | W23: C | X23: B | Y23: D | Z23: D | AB23: C | AC23: B | AD23: C | AE23: C | AF23: A | AG23: D | AH23: D | AI23: B | AJ23: A | AK23: D | AL23: B | AM23: A | AN23: B | AO23: B | AP23: B | AQ23: C | AR23: C
A24: 19 | B24: SISWA 19 | C24: =KELAS -> IX G | D24: 0123013 | E24: D | F24: A | G24: B | I24: C | J24: C | K24: D | L24: D | M24: B | O24: C | P24: C | Q24: D | R24: A | S24: D | T24: C | U24: B | V24: C | W24: D | X24: A | Y24: B | AA24: A | AB24: C | AC24: D | AD24: C | AE24: B | AG24: C | AH24: D | AI24: B | AJ24: C | AK24: D | AL24: B | AM24: D | AN24: B | AO24: A | AP24: B | AQ24: D | AR24: C
A25: 20 | B25: SISWA 20 | C25: =KELAS -> IX G | D25: 0123012 | E25: A | F25: D | G25: B | H25: A | I25: C | J25: B | K25: B | L25: D | M25: B | N25: A | O25: C | P25: C | Q25: D | R25: B | S25: B | T25: C | U25: C | V25: A | W25: D | X25: B | Y25: D | Z25: C | AA25: A | AB25: A | AC25: D | AD25: C | AE25: C | AF25: C | AG25: D | AH25: D | AI25: B | AJ25: B | AK25: C | AL25: D | AM25: A | AN25: B | AO25: B | AP25: B | AQ25: D | AR25: C
A26: 21 | B26: SISWA 21 | C26: =KELAS -> IX G | D26: 0123011 | E26: C | F26: D | G26: B | H26: A | I26: C | J26: C | K26: B | L26: B | M26: C | N26: C | O26: C | P26: C | Q26: D | R26: A | S26: D | T26: C | U26: C | V26: A | W26: C | X26: B | Y26: D | Z26: D | AA26: D | AB26: C | AC26: C | AD26: D | AE26: C | AF26: C | AG26: D | AH26: A | AI26: B | AJ26: D | AK26: D | AL26: B | AM26: A | AN26: B | AO26: A | AP26: B | AQ26: C | AR26: A
A27: 22 | B27: SISWA 22 | C27: =KELAS -> IX G | D27: 0123010 | E27: A | F27: D | G27: A | H27: A | I27: A | J27: C | K27: B | L27: D | M27: C | N27: A | O27: C | P27: C | Q27: B | R27: A | S27: D | T27: C | U27: D | V27: A | W27: A | X27: B | Y27: C | Z27: D | AA27: C | AB27: A | AC27: D | AD27: C | AE27: C | AF27: C | AG27: D | AH27: D | AI27: D | AJ27: D | AK27: D | AL27: B | AM27: A | AN27: A | AO27: C | AP27: B | AQ27: C | AR27: C
A28: 23 | B28: SISWA 23 | C28: =KELAS -> IX G | D28: 012309 | E28: D | F28: D | H28: D | I28: D | J28: C | K28: B | L28: D | M28: D | N28: C | O28: C | P28: D | Q28: D | R28: A | S28: B | T28: A | U28: C | V28: C | W28: B | X28: B | Y28: C | Z28: D | AA28: A | AB28: C | AC28: B | AD28: C | AE28: C | AF28: C | AG28: D | AH28: D | AI28: B | AJ28: A | AK28: C | AL28: B | AM28: C | AN28: C | AO28: B | AP28: B | AQ28: B | AR28: C
A29: 24 | B29: SISWA 24 | C29: =KELAS -> IX G | D29: 012308 | E29: B | F29: C | G29: B | H29: A | I29: B | J29: D | K29: B | L29: A | M29: B | N29: A | O29: C | P29: B | Q29: B | R29: A | S29: A | T29: C | U29: C | V29: D | W29: C | X29: D | Y29: B | Z29: D | AA29: A | AB29: A | AC29: A | AD29: C | AE29: C | AF29: C | AG29: D | AH29: A | AI29: C | AJ29: C | AK29: C | AL29: C | AM29: A | AN29: A | AO29: B | AP29: D | AQ29: D | AR29: A
A30: 25 | B30: SISWA 25 | C30: =KELAS -> IX G | D30: 012307 | E30: D | F30: A | G30: B | H30: A | I30: C | J30: C | K30: C | L30: D | M30: D | N30: C | O30: C | P30: D | Q30: D | R30: A | T30: D | U30: C | V30: A | W30: D | X30: B | Y30: D | Z30: D | AA30: A | AB30: C | AC30: D | AD30: C | AE30: C | AF30: C | AG30: D | AH30: D | AI30: B | AJ30: B | AK30: C | AL30: C | AN30: B | AO30: B | AP30: B | AQ30: D | AR30: A
A31: 26 | B31: SISWA 26 | C31: =KELAS -> IX G | D31: 012306 | E31: A | F31: D | G31: B | H31: A | I31: C | J31: A | K31: A | L31: D | M31: B | N31: A | O31: C | P31: B | Q31: D | R31: D | S31: A | T31: B | U31: D | V31: A | W31: B | X31: C | Y31: C | Z31: C | AA31: A | AB31: A | AC31: D | AD31: B | AE31: D | AF31: D | AG31: A | AH31: D | AI31: C | AJ31: B | AL31: D | AM31: D | AN31: D | AO31: B | AP31: C | AQ31: D | AR31: C
A32: 27 | B32: SISWA 28 | C32: =KELAS -> IX G | D32: 012304 | E32: A | F32: D | G32: D | H32: A | I32: D | J32: A | K32: B | L32: D | M32: D | N32: C | O32: C | P32: C | Q32: C | R32: B | S32: B | T32: C | U32: A | V32: B | W32: C | X32: B | Z32: D | AA32: A | AB32: A | AC32: D | AD32: C | AE32: D | AF32: A | AG32: D | AH32: D | AI32: B | AJ32: B | AK32: D | AL32: B | AM32: B | AN32: C | AO32: A | AP32: D | AQ32: C | AR32: C
A33: 28 | B33: SISWA 29 | C33: =KELAS -> IX G | D33: 012303 | E33: A | F33: D | G33: B | H33: B | I33: C | J33: C | L33: D | M33: D | N33: A | O33: A | P33: C | Q33: A | R33: A | S33: B | T33: C | U33: B | V33: D | W33: B | X33: B | Y33: D | Z33: D | AA33: D | AB33: C | AC33: D | AD33: C | AE33: C | AF33: C | AG33: A | AI33: B | AJ33: B | AK33: D | AL33: C | AM33: A | AN33: D | AO33: A | AP33: B | AQ33: D | AR33: C
A34: 29 | B34: SISWA 30 | C34: =KELAS -> IX G | D34: 012302 | E34: A | F34: D | G34: B | H34: A | J34: B | K34: C | L34: D | M34: D | N34: D | O34: A | P34: B | Q34: D | R34: C | S34: B | T34: C | U34: A | W34: C | X34: B | Y34: D | Z34: D | AA34: A | AB34: C | AC34: D | AD34: C | AE34: A | AF34: B | AG34: C | AH34: A | AI34: B | AJ34: B | AK34: A | AL34: B | AM34: A | AN34: A | AO34: D | AP34: A | AQ34: B | AR34: C
A35: 30 | B35: SISWA 31 | C35: =KELAS -> IX G | D35: 012301 | E35: A | F35: D | G35: A | H35: C | I35: A | J35: A | K35: B | L35: D | M35: D | N35: B | O35: A | P35: C | Q35: D | R35: C | S35: A | T35: D | U35: C | V35: A | W35: C | X35: B | Y35: A | Z35: C | AA35: A | AB35: C | AC35: D | AD35: B | AE35: D | AF35: A | AG35: A | AH35: A | AI35: B | AJ35: B | AK35: C | AL35: A | AM35: B | AN35: B | AO35: C | AP35: B | AQ35: D | AR35: D
A36: 31 | B36: SISWA 32 | D36: 012300 | F36: D | G36: B | H36: A | I36: A | J36: C | K36: D | L36: D | M36: C | N36: C | O36: C | P36: B | Q36: C | R36: A | S36: C | U36: C | V36: B | W36: C | X36: B | Y36: C | Z36: C | AA36: A | AB36: C | AC36: B | AD36: A | AE36: C | AF36: C | AG36: B | AH36: C | AI36: A | AJ36: B | AK36: D | AL36: B | AM36: D | AN36: A | AO36: C | AP36: B | AQ36: D
A37: 32
A38: 33
A39: 34
A40: 35
...

Sheet SKOR
A1: MATRIKS SKOR (1 = benar, 0 = salah)
A2: =UPPER(NAMA_MADRASAH)&" | TAHUN PELAJARAN "&TAHUN_AJAR -> MTSN 3 SUBANG | TAHUN PELAJARAN 2025-2026
A3: =MAPEL&" | Kelas "&KELAS&" | Semester "&SEMESTER&" | "&JENIS_TES -> Bahasa Indonesia | Kelas IX G | Semester Ganjil | Penilaian Akhir Semester
D4: Kunci | E4: =IF(INDEX(KUNCI!$B$6:$B$45,E$5)="","",UPPER(INDEX(KUNCI!$B$6:$B$45,E$5))) -> A | F4: =IF(INDEX(KUNCI!$B$6:$B$45,F$5)="","",UPPER(INDEX(KUNCI!$B$6:$B$45,F$5))) -> D | G4: =IF(INDEX(KUNCI!$B$6:$B$45,G$5)="","",UPPER(INDEX(KUNCI!$B$6:$B$45,G$5))) -> B | H4: =IF(INDEX(KUNCI!$B$6:$B$45,H$5)="","",UPPER(INDEX(KUNCI!$B$6:$B$45,H$5))) -> A | I4: =IF(INDEX(KUNCI!$B$6:$B$45,I$5)="","",UPPER(INDEX(KUNCI!$B$6:$B$45,I$5))) -> C | J4: =IF(INDEX(KUNCI!$B$6:$B$45,J$5)="","",UPPER(INDEX(KUNCI!$B$6:$B$45,J$5))) -> C | K4: =IF(INDEX(KUNCI!$B$6:$B$45,K$5)="","",UPPER(INDEX(KUNCI!$B$6:$B$45,K$5))) -> B | L4: =IF(INDEX(KUNCI!$B$6:$B$45,L$5)="","",UPPER(INDEX(KUNCI!$B$6:$B$45,L$5))) -> D | ... AR4: =IF(INDEX(KUNCI!$B$6:$B$45,AR$5)="","",UPPER(INDEX(KUNCI!$B$6:$B$45,AR$5))) -> C
A5: No | B5: Nama Siswa | C5: Kelas | D5: NISN | E5: 1 | F5: 2 | G5: 3 | H5: 4 | I5: 5 | J5: 6 | K5: 7 | L5: 8 | M5: 9 | N5: 10 | O5: 11 | P5: 12 | Q5: 13 | R5: 14 | S5: 15 | T5: 16 | U5: 17 | V5: 18 | W5: 19 | X5: 20 | Y5: 21 | Z5: 22 | AA5: 23 | AB5: 24 | AC5: 25 | AD5: 26 | AE5: 27 | AF5: 28 | AG5: 29 | AH5: 30 | AI5: 31 | AJ5: 32 | AK5: 33 | AL5: 34 | AM5: 35 | AN5: 36 | AO5: 37 | AP5: 38 | AQ5: 39 | AR5: 40 | AS5: Skor | AT5: Nilai | AU5: Ketuntasan | AV5: Kunci urut (bantu) | AW5: Urutan unik | AX5: Peringkat | AY5: Kelompok
A6: 1 | B6: =IF(JAWABAN!B6="","",JAWABAN!B6) -> SISWA 01 | C6: =IF(JAWABAN!C6="","",JAWABAN!C6) -> IX G | D6: =IF(JAWABAN!D6="","",JAWABAN!D6) -> 0123031 | E6: =IF(OR($B6="",E$4=""),"",IF(UPPER(TRIM(JAWABAN!E6))=E$4,1,0)) -> 1 | F6: =IF(OR($B6="",F$4=""),"",IF(UPPER(TRIM(JAWABAN!F6))=F$4,1,0)) -> 0 | G6: =IF(OR($B6="",G$4=""),"",IF(UPPER(TRIM(JAWABAN!G6))=G$4,1,0)) -> 1 | H6: =IF(OR($B6="",H$4=""),"",IF(UPPER(TRIM(JAWABAN!H6))=H$4,1,0)) -> 0 | I6: =IF(OR($B6="",I$4=""),"",IF(UPPER(TRIM(JAWABAN!I6))=I$4,1,0)) -> 1 | J6: =IF(OR($B6="",J$4=""),"",IF(UPPER(TRIM(JAWABAN!J6))=J$4,1,0)) -> 0 | K6: =IF(OR($B6="",K$4=""),"",IF(UPPER(TRIM(JAWABAN!K6))=K$4,1,0)) -> 0 | L6: =IF(OR($B6="",L$4=""),"",IF(UPPER(TRIM(JAWABAN!L6))=L$4,1,0)) -> 1 | ... AR6: =IF(OR($B6="",AR$4=""),"",IF(UPPER(TRIM(JAWABAN!AR6))=AR$4,1,0)) -> 0 | AS6: =IF($B6="","",SUM(E6:AR6)) -> 14 | AT6: =IF(AS6="","",IFERROR(ROUND(AS6/K_SOAL*100,2),"")) -> 35 | AU6: =IF(AT6="","",IF(AT6>=NILAI_KKM,"Tuntas","Belum tuntas")) -> Belum tuntas | AV6: =IF(AS6="","",AS6+(1000-ROW())/100000) -> 14.00994 | AW6: =IF(AV6="","",RANK(AV6,$AV$6:$AV$55)) -> 30 | AX6: =IF(AS6="","",RANK(AS6,$AS$6:$AS$55)) -> 30 | AY6: =IF(AW6="","",IF(AW6<=N_GRUP,"Atas",IF(AW6>N_SISWA-N_GRUP,"Bawah","Tengah"))) -> Bawah
A7: 2 | B7: =IF(JAWABAN!B7="","",JAWABAN!B7) -> SISWA 02 | C7: =IF(JAWABAN!C7="","",JAWABAN!C7) -> IX G | D7: =IF(JAWABAN!D7="","",JAWABAN!D7) -> 0123030 | E7: =IF(OR($B7="",E$4=""),"",IF(UPPER(TRIM(JAWABAN!E7))=E$4,1,0)) -> 0 | F7: =IF(OR($B7="",F$4=""),"",IF(UPPER(TRIM(JAWABAN!F7))=F$4,1,0)) -> 1 | G7: =IF(OR($B7="",G$4=""),"",IF(UPPER(TRIM(JAWABAN!G7))=G$4,1,0)) -> 0 | H7: =IF(OR($B7="",H$4=""),"",IF(UPPER(TRIM(JAWABAN!H7))=H$4,1,0)) -> 1 | I7: =IF(OR($B7="",I$4=""),"",IF(UPPER(TRIM(JAWABAN!I7))=I$4,1,0)) -> 1 | J7: =IF(OR($B7="",J$4=""),"",IF(UPPER(TRIM(JAWABAN!J7))=J$4,1,0)) -> 1 | K7: =IF(OR($B7="",K$4=""),"",IF(UPPER(TRIM(JAWABAN!K7))=K$4,1,0)) -> 1 | L7: =IF(OR($B7="",L$4=""),"",IF(UPPER(TRIM(JAWABAN!L7))=L$4,1,0)) -> 1 | ... AR7: =IF(OR($B7="",AR$4=""),"",IF(UPPER(TRIM(JAWABAN!AR7))=AR$4,1,0)) -> 1 | AS7: =IF($B7="","",SUM(E7:AR7)) -> 33 | AT7: =IF(AS7="","",IFERROR(ROUND(AS7/K_SOAL*100,2),"")) -> 82.5 | AU7: =IF(AT7="","",IF(AT7>=NILAI_KKM,"Tuntas","Belum tuntas")) -> Tuntas | AV7: =IF(AS7="","",AS7+(1000-ROW())/100000) -> 33.00993 | AW7: =IF(AV7="","",RANK(AV7,$AV$6:$AV$55)) -> 2 | AX7: =IF(AS7="","",RANK(AS7,$AS$6:$AS$55)) -> 2 | AY7: =IF(AW7="","",IF(AW7<=N_GRUP,"Atas",IF(AW7>N_SISWA-N_GRUP,"Bawah","Tengah"))) -> Atas
A8: 3 | B8: =IF(JAWABAN!B8="","",JAWABAN!B8) -> SISWA 03 | C8: =IF(JAWABAN!C8="","",JAWABAN!C8) -> IX G | D8: =IF(JAWABAN!D8="","",JAWABAN!D8) -> 0123029 | E8: =IF(OR($B8="",E$4=""),"",IF(UPPER(TRIM(JAWABAN!E8))=E$4,1,0)) -> 0 | F8: =IF(OR($B8="",F$4=""),"",IF(UPPER(TRIM(JAWABAN!F8))=F$4,1,0)) -> 0 | G8: =IF(OR($B8="",G$4=""),"",IF(UPPER(TRIM(JAWABAN!G8))=G$4,1,0)) -> 0 | H8: =IF(OR($B8="",H$4=""),"",IF(UPPER(TRIM(JAWABAN!H8))=H$4,1,0)) -> 1 | I8: =IF(OR($B8="",I$4=""),"",IF(UPPER(TRIM(JAWABAN!I8))=I$4,1,0)) -> 0 | J8: =IF(OR($B8="",J$4=""),"",IF(UPPER(TRIM(JAWABAN!J8))=J$4,1,0)) -> 0 | K8: =IF(OR($B8="",K$4=""),"",IF(UPPER(TRIM(JAWABAN!K8))=K$4,1,0)) -> 0 | L8: =IF(OR($B8="",L$4=""),"",IF(UPPER(TRIM(JAWABAN!L8))=L$4,1,0)) -> 1 | ... AR8: =IF(OR($B8="",AR$4=""),"",IF(UPPER(TRIM(JAWABAN!AR8))=AR$4,1,0)) -> 0 | AS8: =IF($B8="","",SUM(E8:AR8)) -> 18 | AT8: =IF(AS8="","",IFERROR(ROUND(AS8/K_SOAL*100,2),"")) -> 45 | AU8: =IF(AT8="","",IF(AT8>=NILAI_KKM,"Tuntas","Belum tuntas")) -> Belum tuntas | AV8: =IF(AS8="","",AS8+(1000-ROW())/100000) -> 18.00992 | AW8: =IF(AV8="","",RANK(AV8,$AV$6:$AV$55)) -> 26 | AX8: =IF(AS8="","",RANK(AS8,$AS$6:$AS$55)) -> 26 | AY8: =IF(AW8="","",IF(AW8<=N_GRUP,"Atas",IF(AW8>N_SISWA-N_GRUP,"Bawah","Tengah"))) -> Bawah
A9: 4 | B9: =IF(JAWABAN!B9="","",JAWABAN!B9) -> SISWA 04 | C9: =IF(JAWABAN!C9="","",JAWABAN!C9) -> IX G | D9: =IF(JAWABAN!D9="","",JAWABAN!D9) -> 0123028 | E9: =IF(OR($B9="",E$4=""),"",IF(UPPER(TRIM(JAWABAN!E9))=E$4,1,0)) -> 0 | F9: =IF(OR($B9="",F$4=""),"",IF(UPPER(TRIM(JAWABAN!F9))=F$4,1,0)) -> 0 | G9: =IF(OR($B9="",G$4=""),"",IF(UPPER(TRIM(JAWABAN!G9))=G$4,1,0)) -> 1 | H9: =IF(OR($B9="",H$4=""),"",IF(UPPER(TRIM(JAWABAN!H9))=H$4,1,0)) -> 1 | I9: =IF(OR($B9="",I$4=""),"",IF(UPPER(TRIM(JAWABAN!I9))=I$4,1,0)) -> 0 | J9: =IF(OR($B9="",J$4=""),"",IF(UPPER(TRIM(JAWABAN!J9))=J$4,1,0)) -> 0 | K9: =IF(OR($B9="",K$4=""),"",IF(UPPER(TRIM(JAWABAN!K9))=K$4,1,0)) -> 1 | L9: =IF(OR($B9="",L$4=""),"",IF(UPPER(TRIM(JAWABAN!L9))=L$4,1,0)) -> 1 | ... AR9: =IF(OR($B9="",AR$4=""),"",IF(UPPER(TRIM(JAWABAN!AR9))=AR$4,1,0)) -> 1 | AS9: =IF($B9="","",SUM(E9:AR9)) -> 20 | AT9: =IF(AS9="","",IFERROR(ROUND(AS9/K_SOAL*100,2),"")) -> 50 | AU9: =IF(AT9="","",IF(AT9>=NILAI_KKM,"Tuntas","Belum tuntas")) -> Belum tuntas | AV9: =IF(AS9="","",AS9+(1000-ROW())/100000) -> 20.00991 | AW9: =IF(AV9="","",RANK(AV9,$AV$6:$AV$55)) -> 21 | AX9: =IF(AS9="","",RANK(AS9,$AS$6:$AS$55)) -> 21 | AY9: =IF(AW9="","",IF(AW9<=N_GRUP,"Atas",IF(AW9>N_SISWA-N_GRUP,"Bawah","Tengah"))) -> Tengah
A10: 5 | B10: =IF(JAWABAN!B10="","",JAWABAN!B10) -> SISWA 05 | C10: =IF(JAWABAN!C10="","",JAWABAN!C10) -> IX G | D10: =IF(JAWABAN!D10="","",JAWABAN!D10) -> 0123027 | E10: =IF(OR($B10="",E$4=""),"",IF(UPPER(TRIM(JAWABAN!E10))=E$4,1,0)) -> 1 | F10: =IF(OR($B10="",F$4=""),"",IF(UPPER(TRIM(JAWABAN!F10))=F$4,1,0)) -> 1 | G10: =IF(OR($B10="",G$4=""),"",IF(UPPER(TRIM(JAWABAN!G10))=G$4,1,0)) -> 1 | H10: =IF(OR($B10="",H$4=""),"",IF(UPPER(TRIM(JAWABAN!H10))=H$4,1,0)) -> 0 | I10: =IF(OR($B10="",I$4=""),"",IF(UPPER(TRIM(JAWABAN!I10))=I$4,1,0)) -> 1 | J10: =IF(OR($B10="",J$4=""),"",IF(UPPER(TRIM(JAWABAN!J10))=J$4,1,0)) -> 0 | K10: =IF(OR($B10="",K$4=""),"",IF(UPPER(TRIM(JAWABAN!K10))=K$4,1,0)) -> 0 | L10: =IF(OR($B10="",L$4=""),"",IF(UPPER(TRIM(JAWABAN!L10))=L$4,1,0)) -> 1 | ... AR10: =IF(OR($B10="",AR$4=""),"",IF(UPPER(TRIM(JAWABAN!AR10))=AR$4,1,0)) -> 1 | AS10: =IF($B10="","",SUM(E10:AR10)) -> 35 | AT10: =IF(AS10="","",IFERROR(ROUND(AS10/K_SOAL*100,2),"")) -> 87.5 | AU10: =IF(AT10="","",IF(AT10>=NILAI_KKM,"Tuntas","Belum tuntas")) -> Tuntas | AV10: =IF(AS10="","",AS10+(1000-ROW())/100000) -> 35.0099 | AW10: =IF(AV10="","",RANK(AV10,$AV$6:$AV$55)) -> 1 | AX10: =IF(AS10="","",RANK(AS10,$AS$6:$AS$55)) -> 1 | AY10: =IF(AW10="","",IF(AW10<=N_GRUP,"Atas",IF(AW10>N_SISWA-N_GRUP,"Bawah","Tengah"))) -> Atas
A11: 6 | B11: =IF(JAWABAN!B11="","",JAWABAN!B11) -> SISWA 06 | C11: =IF(JAWABAN!C11="","",JAWABAN!C11) -> IX G | D11: =IF(JAWABAN!D11="","",JAWABAN!D11) -> 0123026 | E11: =IF(OR($B11="",E$4=""),"",IF(UPPER(TRIM(JAWABAN!E11))=E$4,1,0)) -> 0 | F11: =IF(OR($B11="",F$4=""),"",IF(UPPER(TRIM(JAWABAN!F11))=F$4,1,0)) -> 0 | G11: =IF(OR($B11="",G$4=""),"",IF(UPPER(TRIM(JAWABAN!G11))=G$4,1,0)) -> 0 | H11: =IF(OR($B11="",H$4=""),"",IF(UPPER(TRIM(JAWABAN!H11))=H$4,1,0)) -> 1 | I11: =IF(OR($B11="",I$4=""),"",IF(UPPER(TRIM(JAWABAN!I11))=I$4,1,0)) -> 0 | J11: =IF(OR($B11="",J$4=""),"",IF(UPPER(TRIM(JAWABAN!J11))=J$4,1,0)) -> 1 | K11: =IF(OR($B11="",K$4=""),"",IF(UPPER(TRIM(JAWABAN!K11))=K$4,1,0)) -> 1 | L11: =IF(OR($B11="",L$4=""),"",IF(UPPER(TRIM(JAWABAN!L11))=L$4,1,0)) -> 1 | ... AR11: =IF(OR($B11="",AR$4=""),"",IF(UPPER(TRIM(JAWABAN!AR11))=AR$4,1,0)) -> 0 | AS11: =IF($B11="","",SUM(E11:AR11)) -> 29 | AT11: =IF(AS11="","",IFERROR(ROUND(AS11/K_SOAL*100,2),"")) -> 72.5 | AU11: =IF(AT11="","",IF(AT11>=NILAI_KKM,"Tuntas","Belum tuntas")) -> Belum tuntas | AV11: =IF(AS11="","",AS11+(1000-ROW())/100000) -> 29.00989 | AW11: =IF(AV11="","",RANK(AV11,$AV$6:$AV$55)) -> 7 | AX11: =IF(AS11="","",RANK(AS11,$AS$6:$AS$55)) -> 7 | AY11: =IF(AW11="","",IF(AW11<=N_GRUP,"Atas",IF(AW11>N_SISWA-N_GRUP,"Bawah","Tengah"))) -> Atas
A12: 7 | B12: =IF(JAWABAN!B12="","",JAWABAN!B12) -> SISWA 07 | C12: =IF(JAWABAN!C12="","",JAWABAN!C12) -> IX G | D12: =IF(JAWABAN!D12="","",JAWABAN!D12) -> 0123025 | E12: =IF(OR($B12="",E$4=""),"",IF(UPPER(TRIM(JAWABAN!E12))=E$4,1,0)) -> 1 | F12: =IF(OR($B12="",F$4=""),"",IF(UPPER(TRIM(JAWABAN!F12))=F$4,1,0)) -> 0 | G12: =IF(OR($B12="",G$4=""),"",IF(UPPER(TRIM(JAWABAN!G12))=G$4,1,0)) -> 1 | H12: =IF(OR($B12="",H$4=""),"",IF(UPPER(TRIM(JAWABAN!H12))=H$4,1,0)) -> 1 | I12: =IF(OR($B12="",I$4=""),"",IF(UPPER(TRIM(JAWABAN!I12))=I$4,1,0)) -> 0 | J12: =IF(OR($B12="",J$4=""),"",IF(UPPER(TRIM(JAWABAN!J12))=J$4,1,0)) -> 1 | K12: =IF(OR($B12="",K$4=""),"",IF(UPPER(TRIM(JAWABAN!K12))=K$4,1,0)) -> 1 | L12: =IF(OR($B12="",L$4=""),"",IF(UPPER(TRIM(JAWABAN!L12))=L$4,1,0)) -> 1 | ... AR12: =IF(OR($B12="",AR$4=""),"",IF(UPPER(TRIM(JAWABAN!AR12))=AR$4,1,0)) -> 1 | AS12: =IF($B12="","",SUM(E12:AR12)) -> 23 | AT12: =IF(AS12="","",IFERROR(ROUND(AS12/K_SOAL*100,2),"")) -> 57.5 | AU12: =IF(AT12="","",IF(AT12>=NILAI_KKM,"Tuntas","Belum tuntas")) -> Belum tuntas | AV12: =IF(AS12="","",AS12+(1000-ROW())/100000) -> 23.00988 | AW12: =IF(AV12="","",RANK(AV12,$AV$6:$AV$55)) -> 16 | AX12: =IF(AS12="","",RANK(AS12,$AS$6:$AS$55)) -> 16 | AY12: =IF(AW12="","",IF(AW12<=N_GRUP,"Atas",IF(AW12>N_SISWA-N_GRUP,"Bawah","Tengah"))) -> Tengah
A13: 8 | B13: =IF(JAWABAN!B13="","",JAWABAN!B13) -> SISWA 08 | C13: =IF(JAWABAN!C13="","",JAWABAN!C13) -> IX G | D13: =IF(JAWABAN!D13="","",JAWABAN!D13) -> 0123024 | E13: =IF(OR($B13="",E$4=""),"",IF(UPPER(TRIM(JAWABAN!E13))=E$4,1,0)) -> 0 | F13: =IF(OR($B13="",F$4=""),"",IF(UPPER(TRIM(JAWABAN!F13))=F$4,1,0)) -> 0 | G13: =IF(OR($B13="",G$4=""),"",IF(UPPER(TRIM(JAWABAN!G13))=G$4,1,0)) -> 0 | H13: =IF(OR($B13="",H$4=""),"",IF(UPPER(TRIM(JAWABAN!H13))=H$4,1,0)) -> 0 | I13: =IF(OR($B13="",I$4=""),"",IF(UPPER(TRIM(JAWABAN!I13))=I$4,1,0)) -> 1 | J13: =IF(OR($B13="",J$4=""),"",IF(UPPER(TRIM(JAWABAN!J13))=J$4,1,0)) -> 0 | K13: =IF(OR($B13="",K$4=""),"",IF(UPPER(TRIM(JAWABAN!K13))=K$4,1,0)) -> 1 | L13: =IF(OR($B13="",L$4=""),"",IF(UPPER(TRIM(JAWABAN!L13))=L$4,1,0)) -> 1 | ... AR13: =IF(OR($B13="",AR$4=""),"",IF(UPPER(TRIM(JAWABAN!AR13))=AR$4,1,0)) -> 1 | AS13: =IF($B13="","",SUM(E13:AR13)) -> 17 | AT13: =IF(AS13="","",IFERROR(ROUND(AS13/K_SOAL*100,2),"")) -> 42.5 | AU13: =IF(AT13="","",IF(AT13>=NILAI_KKM,"Tuntas","Belum tuntas")) -> Belum tuntas | AV13: =IF(AS13="","",AS13+(1000-ROW())/100000) -> 17.00987 | AW13: =IF(AV13="","",RANK(AV13,$AV$6:$AV$55)) -> 27 | AX13: =IF(AS13="","",RANK(AS13,$AS$6:$AS$55)) -> 27 | AY13: =IF(AW13="","",IF(AW13<=N_GRUP,"Atas",IF(AW13>N_SISWA-N_GRUP,"Bawah","Tengah"))) -> Bawah
A14: 9 | B14: =IF(JAWABAN!B14="","",JAWABAN!B14) -> SISWA 09 | C14: =IF(JAWABAN!C14="","",JAWABAN!C14) -> IX G | D14: =IF(JAWABAN!D14="","",JAWABAN!D14) -> 0123023 | E14: =IF(OR($B14="",E$4=""),"",IF(UPPER(TRIM(JAWABAN!E14))=E$4,1,0)) -> 1 | F14: =IF(OR($B14="",F$4=""),"",IF(UPPER(TRIM(JAWABAN!F14))=F$4,1,0)) -> 1 | G14: =IF(OR($B14="",G$4=""),"",IF(UPPER(TRIM(JAWABAN!G14))=G$4,1,0)) -> 1 | H14: =IF(OR($B14="",H$4=""),"",IF(UPPER(TRIM(JAWABAN!H14))=H$4,1,0)) -> 0 | I14: =IF(OR($B14="",I$4=""),"",IF(UPPER(TRIM(JAWABAN!I14))=I$4,1,0)) -> 1 | J14: =IF(OR($B14="",J$4=""),"",IF(UPPER(TRIM(JAWABAN!J14))=J$4,1,0)) -> 0 | K14: =IF(OR($B14="",K$4=""),"",IF(UPPER(TRIM(JAWABAN!K14))=K$4,1,0)) -> 0 | L14: =IF(OR($B14="",L$4=""),"",IF(UPPER(TRIM(JAWABAN!L14))=L$4,1,0)) -> 0 | ... AR14: =IF(OR($B14="",AR$4=""),"",IF(UPPER(TRIM(JAWABAN!AR14))=AR$4,1,0)) -> 1 | AS14: =IF($B14="","",SUM(E14:AR14)) -> 19 | AT14: =IF(AS14="","",IFERROR(ROUND(AS14/K_SOAL*100,2),"")) -> 47.5 | AU14: =IF(AT14="","",IF(AT14>=NILAI_KKM,"Tuntas","Belum tuntas")) -> Belum tuntas | AV14: =IF(AS14="","",AS14+(1000-ROW())/100000) -> 19.00986 | AW14: =IF(AV14="","",RANK(AV14,$AV$6:$AV$55)) -> 24 | AX14: =IF(AS14="","",RANK(AS14,$AS$6:$AS$55)) -> 24 | AY14: =IF(AW14="","",IF(AW14<=N_GRUP,"Atas",IF(AW14>N_SISWA-N_GRUP,"Bawah","Tengah"))) -> Bawah
A15: 10 | B15: =IF(JAWABAN!B15="","",JAWABAN!B15) -> SISWA 10 | C15: =IF(JAWABAN!C15="","",JAWABAN!C15) -> IX G | D15: =IF(JAWABAN!D15="","",JAWABAN!D15) -> 0123022 | E15: =IF(OR($B15="",E$4=""),"",IF(UPPER(TRIM(JAWABAN!E15))=E$4,1,0)) -> 1 | F15: =IF(OR($B15="",F$4=""),"",IF(UPPER(TRIM(JAWABAN!F15))=F$4,1,0)) -> 1 | G15: =IF(OR($B15="",G$4=""),"",IF(UPPER(TRIM(JAWABAN!G15))=G$4,1,0)) -> 1 | H15: =IF(OR($B15="",H$4=""),"",IF(UPPER(TRIM(JAWABAN!H15))=H$4,1,0)) -> 1 | I15: =IF(OR($B15="",I$4=""),"",IF(UPPER(TRIM(JAWABAN!I15))=I$4,1,0)) -> 1 | J15: =IF(OR($B15="",J$4=""),"",IF(UPPER(TRIM(JAWABAN!J15))=J$4,1,0)) -> 0 | K15: =IF(OR($B15="",K$4=""),"",IF(UPPER(TRIM(JAWABAN!K15))=K$4,1,0)) -> 0 | L15: =IF(OR($B15="",L$4=""),"",IF(UPPER(TRIM(JAWABAN!L15))=L$4,1,0)) -> 0 | ... AR15: =IF(OR($B15="",AR$4=""),"",IF(UPPER(TRIM(JAWABAN!AR15))=AR$4,1,0)) -> 1 | AS15: =IF($B15="","",SUM(E15:AR15)) -> 20 | AT15: =IF(AS15="","",IFERROR(ROUND(AS15/K_SOAL*100,2),"")) -> 50 | AU15: =IF(AT15="","",IF(AT15>=NILAI_KKM,"Tuntas","Belum tuntas")) -> Belum tuntas | AV15: =IF(AS15="","",AS15+(1000-ROW())/100000) -> 20.00985 | AW15: =IF(AV15="","",RANK(AV15,$AV$6:$AV$55)) -> 22 | AX15: =IF(AS15="","",RANK(AS15,$AS$6:$AS$55)) -> 21 | AY15: =IF(AW15="","",IF(AW15<=N_GRUP,"Atas",IF(AW15>N_SISWA-N_GRUP,"Bawah","Tengah"))) -> Tengah
A16: 11 | B16: =IF(JAWABAN!B16="","",JAWABAN!B16) -> SISWA 11 | C16: =IF(JAWABAN!C16="","",JAWABAN!C16) -> IX G | D16: =IF(JAWABAN!D16="","",JAWABAN!D16) -> 0123021 | E16: =IF(OR($B16="",E$4=""),"",IF(UPPER(TRIM(JAWABAN!E16))=E$4,1,0)) -> 1 | F16: =IF(OR($B16="",F$4=""),"",IF(UPPER(TRIM(JAWABAN!F16))=F$4,1,0)) -> 1 | G16: =IF(OR($B16="",G$4=""),"",IF(UPPER(TRIM(JAWABAN!G16))=G$4,1,0)) -> 0 | H16: =IF(OR($B16="",H$4=""),"",IF(UPPER(TRIM(JAWABAN!H16))=H$4,1,0)) -> 1 | I16: =IF(OR($B16="",I$4=""),"",IF(UPPER(TRIM(JAWABAN!I16))=I$4,1,0)) -> 0 | J16: =IF(OR($B16="",J$4=""),"",IF(UPPER(TRIM(JAWABAN!J16))=J$4,1,0)) -> 1 | K16: =IF(OR($B16="",K$4=""),"",IF(UPPER(TRIM(JAWABAN!K16))=K$4,1,0)) -> 1 | L16: =IF(OR($B16="",L$4=""),"",IF(UPPER(TRIM(JAWABAN!L16))=L$4,1,0)) -> 1 | ... AR16: =IF(OR($B16="",AR$4=""),"",IF(UPPER(TRIM(JAWABAN!AR16))=AR$4,1,0)) -> 1 | AS16: =IF($B16="","",SUM(E16:AR16)) -> 29 | AT16: =IF(AS16="","",IFERROR(ROUND(AS16/K_SOAL*100,2),"")) -> 72.5 | AU16: =IF(AT16="","",IF(AT16>=NILAI_KKM,"Tuntas","Belum tuntas")) -> Belum tuntas | AV16: =IF(AS16="","",AS16+(1000-ROW())/100000) -> 29.00984 | AW16: =IF(AV16="","",RANK(AV16,$AV$6:$AV$55)) -> 8 | AX16: =IF(AS16="","",RANK(AS16,$AS$6:$AS$55)) -> 7 | AY16: =IF(AW16="","",IF(AW16<=N_GRUP,"Atas",IF(AW16>N_SISWA-N_GRUP,"Bawah","Tengah"))) -> Atas
A17: 12 | B17: =IF(JAWABAN!B17="","",JAWABAN!B17) -> SISWA 12 | C17: =IF(JAWABAN!C17="","",JAWABAN!C17) -> IX G | D17: =IF(JAWABAN!D17="","",JAWABAN!D17) -> 0123020 | E17: =IF(OR($B17="",E$4=""),"",IF(UPPER(TRIM(JAWABAN!E17))=E$4,1,0)) -> 1 | F17: =IF(OR($B17="",F$4=""),"",IF(UPPER(TRIM(JAWABAN!F17))=F$4,1,0)) -> 1 | G17: =IF(OR($B17="",G$4=""),"",IF(UPPER(TRIM(JAWABAN!G17))=G$4,1,0)) -> 0 | H17: =IF(OR($B17="",H$4=""),"",IF(UPPER(TRIM(JAWABAN!H17))=H$4,1,0)) -> 1 | I17: =IF(OR($B17="",I$4=""),"",IF(UPPER(TRIM(JAWABAN!I17))=I$4,1,0)) -> 1 | J17: =IF(OR($B17="",J$4=""),"",IF(UPPER(TRIM(JAWABAN!J17))=J$4,1,0)) -> 1 | K17: =IF(OR($B17="",K$4=""),"",IF(UPPER(TRIM(JAWABAN!K17))=K$4,1,0)) -> 0 | L17: =IF(OR($B17="",L$4=""),"",IF(UPPER(TRIM(JAWABAN!L17))=L$4,1,0)) -> 1 | ... AR17: =IF(OR($B17="",AR$4=""),"",IF(UPPER(TRIM(JAWABAN!AR17))=AR$4,1,0)) -> 1 | AS17: =IF($B17="","",SUM(E17:AR17)) -> 23 | AT17: =IF(AS17="","",IFERROR(ROUND(AS17/K_SOAL*100,2),"")) -> 57.5 | AU17: =IF(AT17="","",IF(AT17>=NILAI_KKM,"Tuntas","Belum tuntas")) -> Belum tuntas | AV17: =IF(AS17="","",AS17+(1000-ROW())/100000) -> 23.00983 | AW17: =IF(AV17="","",RANK(AV17,$AV$6:$AV$55)) -> 17 | AX17: =IF(AS17="","",RANK(AS17,$AS$6:$AS$55)) -> 16 | AY17: =IF(AW17="","",IF(AW17<=N_GRUP,"Atas",IF(AW17>N_SISWA-N_GRUP,"Bawah","Tengah"))) -> Tengah
... A55: 50 | B55: =IF(JAWABAN!B55="","",JAWABAN!B55) | C55: =IF(JAWABAN!C55="","",JAWABAN!C55) | D55: =IF(JAWABAN!D55="","",JAWABAN!D55) | E55: =IF(OR($B55="",E$4=""),"",IF(UPPER(TRIM(JAWABAN!E55))=E$4,1,0)) | F55: =IF(OR($B55="",F$4=""),"",IF(UPPER(TRIM(JAWABAN!F55))=F$4,1,0)) | G55: =IF(OR($B55="",G$4=""),"",IF(UPPER(TRIM(JAWABAN!G55))=G$4,1,0)) | H55: =IF(OR($B55="",H$4=""),"",IF(UPPER(TRIM(JAWABAN!H55))=H$4,1,0)) | I55: =IF(OR($B55="",I$4=""),"",IF(UPPER(TRIM(JAWABAN!I55))=I$4,1,0)) | J55: =IF(OR($B55="",J$4=""),"",IF(UPPER(TRIM(JAWABAN!J55))=J$4,1,0)) | K55: =IF(OR($B55="",K$4=""),"",IF(UPPER(TRIM(JAWABAN!K55))=K$4,1,0)) | L55: =IF(OR($B55="",L$4=""),"",IF(UPPER(TRIM(JAWABAN!L55))=L$4,1,0)) | ... AR55: =IF(OR($B55="",AR$4=""),"",IF(UPPER(TRIM(JAWABAN!AR55))=AR$4,1,0)) | AS55: =IF($B55="","",SUM(E55:AR55)) | AT55: =IF(AS55="","",IFERROR(ROUND(AS55/K_SOAL*100,2),"")) | AU55: =IF(AT55="","",IF(AT55>=NILAI_KKM,"Tuntas","Belum tuntas")) | AV55: =IF(AS55="","",AS55+(1000-ROW())/100000) | AW55: =IF(AV55="","",RANK(AV55,$AV$6:$AV$55)) | AX55: =IF(AS55="","",RANK(AS55,$AS$6:$AS$55)) | AY55: =IF(AW55="","",IF(AW55<=N_GRUP,"Atas",IF(AW55>N_SISWA-N_GRUP,"Bawah","Tengah")))

Sheet NILAI
A1: DAFTAR NILAI SISWA
A2: =UPPER(NAMA_MADRASAH)&" | TAHUN PELAJARAN "&TAHUN_AJAR -> MTSN 3 SUBANG | TAHUN PELAJARAN 2025-2026
A3: =MAPEL&" | Kelas "&KELAS&" | Semester "&SEMESTER&" | "&JENIS_TES -> Bahasa Indonesia | Kelas IX G | Semester Ganjil | Penilaian Akhir Semester
A5: No | B5: Nama Siswa | C5: Kelas | D5: Jumlah Benar | E5: Jumlah Salah | F5: Nilai | G5: Keterangan | H5: Peringkat | I5: Kelompok
A6: =IF(SKOR!B6="","",SKOR!A6) -> 1 | B6: =SKOR!B6 -> SISWA 01 | C6: =SKOR!C6 -> IX G | D6: =SKOR!AS6 -> 14 | E6: =IF(D6="","",K_SOAL-D6) -> 26 | F6: =SKOR!AT6 -> 35 | G6: =SKOR!AU6 -> Belum tuntas | H6: =SKOR!AX6 -> 30 | I6: =SKOR!AY6 -> Bawah
A7: =IF(SKOR!B7="","",SKOR!A7) -> 2 | B7: =SKOR!B7 -> SISWA 02 | C7: =SKOR!C7 -> IX G | D7: =SKOR!AS7 -> 33 | E7: =IF(D7="","",K_SOAL-D7) -> 7 | F7: =SKOR!AT7 -> 82.5 | G7: =SKOR!AU7 -> Tuntas | H7: =SKOR!AX7 -> 2 | I7: =SKOR!AY7 -> Atas
A8: =IF(SKOR!B8="","",SKOR!A8) -> 3 | B8: =SKOR!B8 -> SISWA 03 | C8: =SKOR!C8 -> IX G | D8: =SKOR!AS8 -> 18 | E8: =IF(D8="","",K_SOAL-D8) -> 22 | F8: =SKOR!AT8 -> 45 | G8: =SKOR!AU8 -> Belum tuntas | H8: =SKOR!AX8 -> 26 | I8: =SKOR!AY8 -> Bawah
A9: =IF(SKOR!B9="","",SKOR!A9) -> 4 | B9: =SKOR!B9 -> SISWA 04 | C9: =SKOR!C9 -> IX G | D9: =SKOR!AS9 -> 20 | E9: =IF(D9="","",K_SOAL-D9) -> 20 | F9: =SKOR!AT9 -> 50 | G9: =SKOR!AU9 -> Belum tuntas | H9: =SKOR!AX9 -> 21 | I9: =SKOR!AY9 -> Tengah
A10: =IF(SKOR!B10="","",SKOR!A10) -> 5 | B10: =SKOR!B10 -> SISWA 05 | C10: =SKOR!C10 -> IX G | D10: =SKOR!AS10 -> 35 | E10: =IF(D10="","",K_SOAL-D10) -> 5 | F10: =SKOR!AT10 -> 87.5 | G10: =SKOR!AU10 -> Tuntas | H10: =SKOR!AX10 -> 1 | I10: =SKOR!AY10 -> Atas
A11: =IF(SKOR!B11="","",SKOR!A11) -> 6 | B11: =SKOR!B11 -> SISWA 06 | C11: =SKOR!C11 -> IX G | D11: =SKOR!AS11 -> 29 | E11: =IF(D11="","",K_SOAL-D11) -> 11 | F11: =SKOR!AT11 -> 72.5 | G11: =SKOR!AU11 -> Belum tuntas | H11: =SKOR!AX11 -> 7 | I11: =SKOR!AY11 -> Atas
A12: =IF(SKOR!B12="","",SKOR!A12) -> 7 | B12: =SKOR!B12 -> SISWA 07 | C12: =SKOR!C12 -> IX G | D12: =SKOR!AS12 -> 23 | E12: =IF(D12="","",K_SOAL-D12) -> 17 | F12: =SKOR!AT12 -> 57.5 | G12: =SKOR!AU12 -> Belum tuntas | H12: =SKOR!AX12 -> 16 | I12: =SKOR!AY12 -> Tengah
A13: =IF(SKOR!B13="","",SKOR!A13) -> 8 | B13: =SKOR!B13 -> SISWA 08 | C13: =SKOR!C13 -> IX G | D13: =SKOR!AS13 -> 17 | E13: =IF(D13="","",K_SOAL-D13) -> 23 | F13: =SKOR!AT13 -> 42.5 | G13: =SKOR!AU13 -> Belum tuntas | H13: =SKOR!AX13 -> 27 | I13: =SKOR!AY13 -> Bawah
A14: =IF(SKOR!B14="","",SKOR!A14) -> 9 | B14: =SKOR!B14 -> SISWA 09 | C14: =SKOR!C14 -> IX G | D14: =SKOR!AS14 -> 19 | E14: =IF(D14="","",K_SOAL-D14) -> 21 | F14: =SKOR!AT14 -> 47.5 | G14: =SKOR!AU14 -> Belum tuntas | H14: =SKOR!AX14 -> 24 | I14: =SKOR!AY14 -> Bawah
A15: =IF(SKOR!B15="","",SKOR!A15) -> 10 | B15: =SKOR!B15 -> SISWA 10 | C15: =SKOR!C15 -> IX G | D15: =SKOR!AS15 -> 20 | E15: =IF(D15="","",K_SOAL-D15) -> 20 | F15: =SKOR!AT15 -> 50 | G15: =SKOR!AU15 -> Belum tuntas | H15: =SKOR!AX15 -> 21 | I15: =SKOR!AY15 -> Tengah
A16: =IF(SKOR!B16="","",SKOR!A16) -> 11 | B16: =SKOR!B16 -> SISWA 11 | C16: =SKOR!C16 -> IX G | D16: =SKOR!AS16 -> 29 | E16: =IF(D16="","",K_SOAL-D16) -> 11 | F16: =SKOR!AT16 -> 72.5 | G16: =SKOR!AU16 -> Belum tuntas | H16: =SKOR!AX16 -> 7 | I16: =SKOR!AY16 -> Atas
A17: =IF(SKOR!B17="","",SKOR!A17) -> 12 | B17: =SKOR!B17 -> SISWA 12 | C17: =SKOR!C17 -> IX G | D17: =SKOR!AS17 -> 23 | E17: =IF(D17="","",K_SOAL-D17) -> 17 | F17: =SKOR!AT17 -> 57.5 | G17: =SKOR!AU17 -> Belum tuntas | H17: =SKOR!AX17 -> 16 | I17: =SKOR!AY17 -> Tengah
... A55: =IF(SKOR!B55="","",SKOR!A55) | B55: =SKOR!B55 | C55: =SKOR!C55 | D55: =SKOR!AS55 | E55: =IF(D55="","",K_SOAL-D55) | F55: =SKOR!AT55 | G55: =SKOR!AU55 | H55: =SKOR!AX55 | I55: =SKOR!AY55

Sheet ANALISIS
A1: ANALISIS BUTIR SOAL
A2: =UPPER(NAMA_MADRASAH)&" | TAHUN PELAJARAN "&TAHUN_AJAR -> MTSN 3 SUBANG | TAHUN PELAJARAN 2025-2026
A3: =MAPEL&" | Kelas "&KELAS&" | Semester "&SEMESTER&" | "&JENIS_TES -> Bahasa Indonesia | Kelas IX G | Semester Ganjil | Penilaian Akhir Semester
A5: No | B5: Kunci | C5: Jml Benar (B) | D5: Jml Salah | E5: Tingkat Kesukaran (p) | F5: Kategori Kesukaran | G5: Benar Kel. Atas (BA) | H5: Benar Kel. Bawah (BB) | I5: Daya Pembeda (D) | J5: Kategori Daya Pembeda | K5: Rata-rata Skor Penjawab Benar (Mp) | L5: r hitung (r pbis) | M5: r tabel | N5: Validitas | O5: p x q | P5: Pengecoh Berfungsi (dari 3) | Q5: Rekomendasi | R5: Tindak Lanjut | S5: Materi / Indikator | U5: Bantu: Diterima | V5: Bantu: Direvisi | W5: Bantu: Diganti
A6: 1 | B6: =IF(KUNCI!B6="","",UPPER(KUNCI!B6)) -> A | C6: =IF($B6="","",SUM(SKOR!$E$6:$E$55)) -> 17 | D6: =IF($B6="","",N_SISWA-C6) -> 14 | E6: =IF($B6="","",IFERROR(C6/N_SISWA,"")) -> 0.5483871 | F6: =IF(E6="","",IF(E6<=BATAS_SUKAR,"Sukar",IF(E6<=BATAS_MUDAH,"Sedang","Mudah"))) -> Sedang | G6: =IF($B6="","",SUMIFS(SKOR!$E$6:$E$55,SKOR!$AW$6:$AW$55,"<="&N_GRUP)) -> 4 | H6: =IF($B6="","",SUMIFS(SKOR!$E$6:$E$55,SKOR!$AW$6:$AW$55,">"&(N_SISWA-N_GRUP))) -> 4 | I6: =IF($B6="","",IFERROR((G6-H6)/N_GRUP,"")) -> 0 | J6: =IF(I6="","",IF(I6<0,"Sangat jelek",IF(I6<=DP_B1,"Jelek",IF(I6<=DP_B2,"Cukup",IF(I6<=DP_B3,"Baik","Baik sekali"))))) -> Jelek | K6: =IF(OR($B6="",C6=0),"",SUMIFS(SKOR!$AS$6:$AS$55,SKOR!$E$6:$E$55,1)/C6) -> 24.058824 | L6: =IF(K6="","",IFERROR((K6-MEAN_SKOR)/SD_SKOR*SQRT(E6/(1-E6)),"")) -> 0.029229502 | M6: =IF($B6="","",R_TABEL) -> 0.35504589 | N6: =IF($B6="","",IF(L6="","Tidak valid",IF(L6>M6,"Valid","Tidak valid"))) -> Tidak valid | O6: =IF($B6="","",E6*(1-E6)) -> 0.24765869 | P6: =IF($B6="","",PENGECOH!T6) -> 3 | Q6: =IF($B6="","",IF(AND(ISNUMBER(I6),I6<0),"Diganti/Dibuang",IF((N6="Valid")+AND(ISNUMBER(I6),I6>DP_B1)+(F6="Sedang")=3,"Diterima",IF((N6="Valid")+AND(ISNUMBER(I6),I6>DP_B1)+(F6="Sedang")=2,"Direvisi","Diganti/Dibuang")))) -> Diganti/Dibuang | R6: =IF($B6="","",IF(AND(Q6="Diterima",P6=3),"Soal baik; dapat disimpan di bank soal",TRIM(IF(F6="Sukar","Terlalu sukar. ",IF(F6="Mudah","Terlalu mudah. ",""))&IF(N6<>"Valid","Validitas rendah. ","")&IF(AND(ISNUMBER(I6),I6<0),"Daya pembeda negatif (periksa kunci). ",IF(AND(ISNUMBER(I6),I6>DP_B1),"","Daya pembeda rendah. "))&IF(P6<3,"Ada pengecoh tidak berfungsi.","")))) -> Validitas rendah. Daya pembeda rendah. | S6: =IF(KUNCI!C6="","",KUNCI!C6) | T6: =IF($Q6="Diterima",$A6,"") | U6: =IF($Q6="Direvisi",$A6,"") | V6: =IF($Q6="Diganti/Dibuang",$A6,"") -> 1
A7: 2 | B7: =IF(KUNCI!B7="","",UPPER(KUNCI!B7)) -> D | C7: =IF($B7="","",SUM(SKOR!$F$6:$F$55)) -> 21 | D7: =IF($B7="","",N_SISWA-C7) -> 10 | E7: =IF($B7="","",IFERROR(C7/N_SISWA,"")) -> 0.67741935 | F7: =IF(E7="","",IF(E7<=BATAS_SUKAR,"Sukar",IF(E7<=BATAS_MUDAH,"Sedang","Mudah"))) -> Sedang | G7: =IF($B7="","",SUMIFS(SKOR!$F$6:$F$55,SKOR!$AW$6:$AW$55,"<="&N_GRUP)) -> 7 | H7: =IF($B7="","",SUMIFS(SKOR!$F$6:$F$55,SKOR!$AW$6:$AW$55,">"&(N_SISWA-N_GRUP))) -> 4 | I7: =IF($B7="","",IFERROR((G7-H7)/N_GRUP,"")) -> 0.375 | J7: =IF(I7="","",IF(I7<0,"Sangat jelek",IF(I7<=DP_B1,"Jelek",IF(I7<=DP_B2,"Cukup",IF(I7<=DP_B3,"Baik","Baik sekali"))))) -> Cukup | K7: =IF(OR($B7="",C7=0),"",SUMIFS(SKOR!$AS$6:$AS$55,SKOR!$F$6:$F$55,1)/C7) -> 24.952381 | L7: =IF(K7="","",IFERROR((K7-MEAN_SKOR)/SD_SKOR*SQRT(E7/(1-E7)),"")) -> 0.25918335 | M7: =IF($B7="","",R_TABEL) -> 0.35504589 | N7: =IF($B7="","",IF(L7="","Tidak valid",IF(L7>M7,"Valid","Tidak valid"))) -> Tidak valid | O7: =IF($B7="","",E7*(1-E7)) -> 0.21852237 | P7: =IF($B7="","",PENGECOH!T7) -> 3 | Q7: =IF($B7="","",IF(AND(ISNUMBER(I7),I7<0),"Diganti/Dibuang",IF((N7="Valid")+AND(ISNUMBER(I7),I7>DP_B1)+(F7="Sedang")=3,"Diterima",IF((N7="Valid")+AND(ISNUMBER(I7),I7>DP_B1)+(F7="Sedang")=2,"Direvisi","Diganti/Dibuang")))) -> Direvisi | R7: =IF($B7="","",IF(AND(Q7="Diterima",P7=3),"Soal baik; dapat disimpan di bank soal",TRIM(IF(F7="Sukar","Terlalu sukar. ",IF(F7="Mudah","Terlalu mudah. ",""))&IF(N7<>"Valid","Validitas rendah. ","")&IF(AND(ISNUMBER(I7),I7<0),"Daya pembeda negatif (periksa kunci). ",IF(AND(ISNUMBER(I7),I7>DP_B1),"","Daya pembeda rendah. "))&IF(P7<3,"Ada pengecoh tidak berfungsi.","")))) -> Validitas rendah. | S7: =IF(KUNCI!C7="","",KUNCI!C7) | T7: =IF($Q7="Diterima",$A7,"") | U7: =IF($Q7="Direvisi",$A7,"") -> 2 | V7: =IF($Q7="Diganti/Dibuang",$A7,"")
A8: 3 | B8: =IF(KUNCI!B8="","",UPPER(KUNCI!B8)) -> B | C8: =IF($B8="","",SUM(SKOR!$G$6:$G$55)) -> 18 | D8: =IF($B8="","",N_SISWA-C8) -> 13 | E8: =IF($B8="","",IFERROR(C8/N_SISWA,"")) -> 0.58064516 | F8: =IF(E8="","",IF(E8<=BATAS_SUKAR,"Sukar",IF(E8<=BATAS_MUDAH,"Sedang","Mudah"))) -> Sedang | G8: =IF($B8="","",SUMIFS(SKOR!$G$6:$G$55,SKOR!$AW$6:$AW$55,"<="&N_GRUP)) -> 4 | H8: =IF($B8="","",SUMIFS(SKOR!$G$6:$G$55,SKOR!$AW$6:$AW$55,">"&(N_SISWA-N_GRUP))) -> 4 | I8: =IF($B8="","",IFERROR((G8-H8)/N_GRUP,"")) -> 0 | J8: =IF(I8="","",IF(I8<0,"Sangat jelek",IF(I8<=DP_B1,"Jelek",IF(I8<=DP_B2,"Cukup",IF(I8<=DP_B3,"Baik","Baik sekali"))))) -> Jelek | K8: =IF(OR($B8="",C8=0),"",SUMIFS(SKOR!$AS$6:$AS$55,SKOR!$G$6:$G$55,1)/C8) -> 23.666667 | L8: =IF(K8="","",IFERROR((K8-MEAN_SKOR)/SD_SKOR*SQRT(E8/(1-E8)),"")) -> -0.047452821 | M8: =IF($B8="","",R_TABEL) -> 0.35504589 | N8: =IF($B8="","",IF(L8="","Tidak valid",IF(L8>M8,"Valid","Tidak valid"))) -> Tidak valid | O8: =IF($B8="","",E8*(1-E8)) -> 0.24349636 | P8: =IF($B8="","",PENGECOH!T8) -> 3 | Q8: =IF($B8="","",IF(AND(ISNUMBER(I8),I8<0),"Diganti/Dibuang",IF((N8="Valid")+AND(ISNUMBER(I8),I8>DP_B1)+(F8="Sedang")=3,"Diterima",IF((N8="Valid")+AND(ISNUMBER(I8),I8>DP_B1)+(F8="Sedang")=2,"Direvisi","Diganti/Dibuang")))) -> Diganti/Dibuang | R8: =IF($B8="","",IF(AND(Q8="Diterima",P8=3),"Soal baik; dapat disimpan di bank soal",TRIM(IF(F8="Sukar","Terlalu sukar. ",IF(F8="Mudah","Terlalu mudah. ",""))&IF(N8<>"Valid","Validitas rendah. ","")&IF(AND(ISNUMBER(I8),I8<0),"Daya pembeda negatif (periksa kunci). ",IF(AND(ISNUMBER(I8),I8>DP_B1),"","Daya pembeda rendah. "))&IF(P8<3,"Ada pengecoh tidak berfungsi.","")))) -> Validitas rendah. Daya pembeda rendah. | S8: =IF(KUNCI!C8="","",KUNCI!C8) | T8: =IF($Q8="Diterima",$A8,"") | U8: =IF($Q8="Direvisi",$A8,"") | V8: =IF($Q8="Diganti/Dibuang",$A8,"") -> 3
A9: 4 | B9: =IF(KUNCI!B9="","",UPPER(KUNCI!B9)) -> A | C9: =IF($B9="","",SUM(SKOR!$H$6:$H$55)) -> 22 | D9: =IF($B9="","",N_SISWA-C9) -> 9 | E9: =IF($B9="","",IFERROR(C9/N_SISWA,"")) -> 0.70967742 | F9: =IF(E9="","",IF(E9<=BATAS_SUKAR,"Sukar",IF(E9<=BATAS_MUDAH,"Sedang","Mudah"))) -> Mudah | G9: =IF($B9="","",SUMIFS(SKOR!$H$6:$H$55,SKOR!$AW$6:$AW$55,"<="&N_GRUP)) -> 7 | H9: =IF($B9="","",SUMIFS(SKOR!$H$6:$H$55,SKOR!$AW$6:$AW$55,">"&(N_SISWA-N_GRUP))) -> 3 | I9: =IF($B9="","",IFERROR((G9-H9)/N_GRUP,"")) -> 0.5 | J9: =IF(I9="","",IF(I9<0,"Sangat jelek",IF(I9<=DP_B1,"Jelek",IF(I9<=DP_B2,"Cukup",IF(I9<=DP_B3,"Baik","Baik sekali"))))) -> Baik | K9: =IF(OR($B9="",C9=0),"",SUMIFS(SKOR!$AS$6:$AS$55,SKOR!$H$6:$H$55,1)/C9) -> 25.090909 | L9: =IF(K9="","",IFERROR((K9-MEAN_SKOR)/SD_SKOR*SQRT(E9/(1-E9)),"")) -> 0.31655448 | M9: =IF($B9="","",R_TABEL) -> 0.35504589 | N9: =IF($B9="","",IF(L9="","Tidak valid",IF(L9>M9,"Valid","Tidak valid"))) -> Tidak valid | O9: =IF($B9="","",E9*(1-E9)) -> 0.20603538 | P9: =IF($B9="","",PENGECOH!T9) -> 3 | Q9: =IF($B9="","",IF(AND(ISNUMBER(I9),I9<0),"Diganti/Dibuang",IF((N9="Valid")+AND(ISNUMBER(I9),I9>DP_B1)+(F9="Sedang")=3,"Diterima",IF((N9="Valid")+AND(ISNUMBER(I9),I9>DP_B1)+(F9="Sedang")=2,"Direvisi","Diganti/Dibuang")))) -> Diganti/Dibuang | R9: =IF($B9="","",IF(AND(Q9="Diterima",P9=3),"Soal baik; dapat disimpan di bank soal",TRIM(IF(F9="Sukar","Terlalu sukar. ",IF(F9="Mudah","Terlalu mudah. ",""))&IF(N9<>"Valid","Validitas rendah. ","")&IF(AND(ISNUMBER(I9),I9<0),"Daya pembeda negatif (periksa kunci). ",IF(AND(ISNUMBER(I9),I9>DP_B1),"","Daya pembeda rendah. "))&IF(P9<3,"Ada pengecoh tidak berfungsi.","")))) -> Terlalu mudah. Validitas rendah. | S9: =IF(KUNCI!C9="","",KUNCI!C9) | T9: =IF($Q9="Diterima",$A9,"") | U9: =IF($Q9="Direvisi",$A9,"") | V9: =IF($Q9="Diganti/Dibuang",$A9,"") -> 4
A10: 5 | B10: =IF(KUNCI!B10="","",UPPER(KUNCI!B10)) -> C | C10: =IF($B10="","",SUM(SKOR!$I$6:$I$55)) -> 17 | D10: =IF($B10="","",N_SISWA-C10) -> 14 | E10: =IF($B10="","",IFERROR(C10/N_SISWA,"")) -> 0.5483871 | F10: =IF(E10="","",IF(E10<=BATAS_SUKAR,"Sukar",IF(E10<=BATAS_MUDAH,"Sedang","Mudah"))) -> Sedang | G10: =IF($B10="","",SUMIFS(SKOR!$I$6:$I$55,SKOR!$AW$6:$AW$55,"<="&N_GRUP)) -> 6 | H10: =IF($B10="","",SUMIFS(SKOR!$I$6:$I$55,SKOR!$AW$6:$AW$55,">"&(N_SISWA-N_GRUP))) -> 4 | I10: =IF($B10="","",IFERROR((G10-H10)/N_GRUP,"")) -> 0.25 | J10: =IF(I10="","",IF(I10<0,"Sangat jelek",IF(I10<=DP_B1,"Jelek",IF(I10<=DP_B2,"Cukup",IF(I10<=DP_B3,"Baik","Baik sekali"))))) -> Cukup | K10: =IF(OR($B10="",C10=0),"",SUMIFS(SKOR!$AS$6:$AS$55,SKOR!$I$6:$I$55,1)/C10) -> 25.235294 | L10: =IF(K10="","",IFERROR((K10-MEAN_SKOR)/SD_SKOR*SQRT(E10/(1-E10)),"")) -> 0.25023305 | M10: =IF($B10="","",R_TABEL) -> 0.35504589 | N10: =IF($B10="","",IF(L10="","Tidak valid",IF(L10>M10,"Valid","Tidak valid"))) -> Tidak valid | O10: =IF($B10="","",E10*(1-E10)) -> 0.24765869 | P10: =IF($B10="","",PENGECOH!T10) -> 3 | Q10: =IF($B10="","",IF(AND(ISNUMBER(I10),I10<0),"Diganti/Dibuang",IF((N10="Valid")+AND(ISNUMBER(I10),I10>DP_B1)+(F10="Sedang")=3,"Diterima",IF((N10="Valid")+AND(ISNUMBER(I10),I10>DP_B1)+(F10="Sedang")=2,"Direvisi","Diganti/Dibuang")))) -> Direvisi | R10: =IF($B10="","",IF(AND(Q10="Diterima",P10=3),"Soal baik; dapat disimpan di bank soal",TRIM(IF(F10="Sukar","Terlalu sukar. ",IF(F10="Mudah","Terlalu mudah. ",""))&IF(N10<>"Valid","Validitas rendah. ","")&IF(AND(ISNUMBER(I10),I10<0),"Daya pembeda negatif (periksa kunci). ",IF(AND(ISNUMBER(I10),I10>DP_B1),"","Daya pembeda rendah. "))&IF(P10<3,"Ada pengecoh tidak berfungsi.","")))) -> Validitas rendah. | S10: =IF(KUNCI!C10="","",KUNCI!C10) | T10: =IF($Q10="Diterima",$A10,"") | U10: =IF($Q10="Direvisi",$A10,"") -> 5 | V10: =IF($Q10="Diganti/Dibuang",$A10,"")
A11: 6 | B11: =IF(KUNCI!B11="","",UPPER(KUNCI!B11)) -> C | C11: =IF($B11="","",SUM(SKOR!$J$6:$J$55)) -> 16 | D11: =IF($B11="","",N_SISWA-C11) -> 15 | E11: =IF($B11="","",IFERROR(C11/N_SISWA,"")) -> 0.51612903 | F11: =IF(E11="","",IF(E11<=BATAS_SUKAR,"Sukar",IF(E11<=BATAS_MUDAH,"Sedang","Mudah"))) -> Sedang | G11: =IF($B11="","",SUMIFS(SKOR!$J$6:$J$55,SKOR!$AW$6:$AW$55,"<="&N_GRUP)) -> 6 | H11: =IF($B11="","",SUMIFS(SKOR!$J$6:$J$55,SKOR!$AW$6:$AW$55,">"&(N_SISWA-N_GRUP))) -> 0 | I11: =IF($B11="","",IFERROR((G11-H11)/N_GRUP,"")) -> 0.75 | J11: =IF(I11="","",IF(I11<0,"Sangat jelek",IF(I11<=DP_B1,"Jelek",IF(I11<=DP_B2,"Cukup",IF(I11<=DP_B3,"Baik","Baik sekali"))))) -> Baik sekali | K11: =IF(OR($B11="",C11=0),"",SUMIFS(SKOR!$AS$6:$AS$55,SKOR!$J$6:$J$55,1)/C11) -> 27.0625 | L11: =IF(K11="","",IFERROR((K11-MEAN_SKOR)/SD_SKOR*SQRT(E11/(1-E11)),"")) -> 0.55623641 | M11: =IF($B11="","",R_TABEL) -> 0.35504589 | N11: =IF($B11="","",IF(L11="","Tidak valid",IF(L11>M11,"Valid","Tidak valid"))) -> Valid | O11: =IF($B11="","",E11*(1-E11)) -> 0.24973985 | P11: =IF($B11="","",PENGECOH!T11) -> 3 | Q11: =IF($B11="","",IF(AND(ISNUMBER(I11),I11<0),"Diganti/Dibuang",IF((N11="Valid")+AND(ISNUMBER(I11),I11>DP_B1)+(F11="Sedang")=3,"Diterima",IF((N11="Valid")+AND(ISNUMBER(I11),I11>DP_B1)+(F11="Sedang")=2,"Direvisi","Diganti/Dibuang")))) -> Diterima | R11: =IF($B11="","",IF(AND(Q11="Diterima",P11=3),"Soal baik; dapat disimpan di bank soal",TRIM(IF(F11="Sukar","Terlalu sukar. ",IF(F11="Mudah","Terlalu mudah. ",""))&IF(N11<>"Valid","Validitas rendah. ","")&IF(AND(ISNUMBER(I11),I11<0),"Daya pembeda negatif (periksa kunci). ",IF(AND(ISNUMBER(I11),I11>DP_B1),"","Daya pembeda rendah. "))&IF(P11<3,"Ada pengecoh tidak berfungsi.","")))) -> Soal baik; dapat disimpan di bank soal | S11: =IF(KUNCI!C11="","",KUNCI!C11) | T11: =IF($Q11="Diterima",$A11,"") -> 6 | U11: =IF($Q11="Direvisi",$A11,"") | V11: =IF($Q11="Diganti/Dibuang",$A11,"")
A12: 7 | B12: =IF(KUNCI!B12="","",UPPER(KUNCI!B12)) -> B | C12: =IF($B12="","",SUM(SKOR!$K$6:$K$55)) -> 18 | D12: =IF($B12="","",N_SISWA-C12) -> 13 | E12: =IF($B12="","",IFERROR(C12/N_SISWA,"")) -> 0.58064516 | F12: =IF(E12="","",IF(E12<=BATAS_SUKAR,"Sukar",IF(E12<=BATAS_MUDAH,"Sedang","Mudah"))) -> Sedang | G12: =IF($B12="","",SUMIFS(SKOR!$K$6:$K$55,SKOR!$AW$6:$AW$55,"<="&N_GRUP)) -> 7 | H12: =IF($B12="","",SUMIFS(SKOR!$K$6:$K$55,SKOR!$AW$6:$AW$55,">"&(N_SISWA-N_GRUP))) -> 3 | I12: =IF($B12="","",IFERROR((G12-H12)/N_GRUP,"")) -> 0.5 | J12: =IF(I12="","",IF(I12<0,"Sangat jelek",IF(I12<=DP_B1,"Jelek",IF(I12<=DP_B2,"Cukup",IF(I12<=DP_B3,"Baik","Baik sekali"))))) -> Baik | K12: =IF(OR($B12="",C12=0),"",SUMIFS(SKOR!$AS$6:$AS$55,SKOR!$K$6:$K$55,1)/C12) -> 25.833333 | L12: =IF(K12="","",IFERROR((K12-MEAN_SKOR)/SD_SKOR*SQRT(E12/(1-E12)),"")) -> 0.38717188 | M12: =IF($B12="","",R_TABEL) -> 0.35504589 | N12: =IF($B12="","",IF(L12="","Tidak valid",IF(L12>M12,"Valid","Tidak valid"))) -> Valid | O12: =IF($B12="","",E12*(1-E12)) -> 0.24349636 | P12: =IF($B12="","",PENGECOH!T12) -> 2 | Q12: =IF($B12="","",IF(AND(ISNUMBER(I12),I12<0),"Diganti/Dibuang",IF((N12="Valid")+AND(ISNUMBER(I12),I12>DP_B1)+(F12="Sedang")=3,"Diterima",IF((N12="Valid")+AND(ISNUMBER(I12),I12>DP_B1)+(F12="Sedang")=2,"Direvisi","Diganti/Dibuang")))) -> Diterima | R12: =IF($B12="","",IF(AND(Q12="Diterima",P12=3),"Soal baik; dapat disimpan di bank soal",TRIM(IF(F12="Sukar","Terlalu sukar. ",IF(F12="Mudah","Terlalu mudah. ",""))&IF(N12<>"Valid","Validitas rendah. ","")&IF(AND(ISNUMBER(I12),I12<0),"Daya pembeda negatif (periksa kunci). ",IF(AND(ISNUMBER(I12),I12>DP_B1),"","Daya pembeda rendah. "))&IF(P12<3,"Ada pengecoh tidak berfungsi.","")))) -> Ada pengecoh tidak berfungsi. | S12: =IF(KUNCI!C12="","",KUNCI!C12) | T12: =IF($Q12="Diterima",$A12,"") -> 7 | U12: =IF($Q12="Direvisi",$A12,"") | V12: =IF($Q12="Diganti/Dibuang",$A12,"")
A13: 8 | B13: =IF(KUNCI!B13="","",UPPER(KUNCI!B13)) -> D | C13: =IF($B13="","",SUM(SKOR!$L$6:$L$55)) -> 26 | D13: =IF($B13="","",N_SISWA-C13) -> 5 | E13: =IF($B13="","",IFERROR(C13/N_SISWA,"")) -> 0.83870968 | F13: =IF(E13="","",IF(E13<=BATAS_SUKAR,"Sukar",IF(E13<=BATAS_MUDAH,"Sedang","Mudah"))) -> Mudah | G13: =IF($B13="","",SUMIFS(SKOR!$L$6:$L$55,SKOR!$AW$6:$AW$55,"<="&N_GRUP)) -> 8 | H13: =IF($B13="","",SUMIFS(SKOR!$L$6:$L$55,SKOR!$AW$6:$AW$55,">"&(N_SISWA-N_GRUP))) -> 5 | I13: =IF($B13="","",IFERROR((G13-H13)/N_GRUP,"")) -> 0.375 | J13: =IF(I13="","",IF(I13<0,"Sangat jelek",IF(I13<=DP_B1,"Jelek",IF(I13<=DP_B2,"Cukup",IF(I13<=DP_B3,"Baik","Baik sekali"))))) -> Cukup | K13: =IF(OR($B13="",C13=0),"",SUMIFS(SKOR!$AS$6:$AS$55,SKOR!$L$6:$L$55,1)/C13) -> 24.769231 | L13: =IF(K13="","",IFERROR((K13-MEAN_SKOR)/SD_SKOR*SQRT(E13/(1-E13)),"")) -> 0.3366509 | M13: =IF($B13="","",R_TABEL) -> 0.35504589 | N13: =IF($B13="","",IF(L13="","Tidak valid",IF(L13>M13,"Valid","Tidak valid"))) -> Tidak valid | O13: =IF($B13="","",E13*(1-E13)) -> 0.13527575 | P13: =IF($B13="","",PENGECOH!T13) -> 2 | Q13: =IF($B13="","",IF(AND(ISNUMBER(I13),I13<0),"Diganti/Dibuang",IF((N13="Valid")+AND(ISNUMBER(I13),I13>DP_B1)+(F13="Sedang")=3,"Diterima",IF((N13="Valid")+AND(ISNUMBER(I13),I13>DP_B1)+(F13="Sedang")=2,"Direvisi","Diganti/Dibuang")))) -> Diganti/Dibuang | R13: =IF($B13="","",IF(AND(Q13="Diterima",P13=3),"Soal baik; dapat disimpan di bank soal",TRIM(IF(F13="Sukar","Terlalu sukar. ",IF(F13="Mudah","Terlalu mudah. ",""))&IF(N13<>"Valid","Validitas rendah. ","")&IF(AND(ISNUMBER(I13),I13<0),"Daya pembeda negatif (periksa kunci). ",IF(AND(ISNUMBER(I13),I13>DP_B1),"","Daya pembeda rendah. "))&IF(P13<3,"Ada pengecoh tidak berfungsi.","")))) -> Terlalu mudah. Validitas rendah. Ada pengecoh tidak berfungsi. | S13: =IF(KUNCI!C13="","",KUNCI!C13) | T13: =IF($Q13="Diterima",$A13,"") | U13: =IF($Q13="Direvisi",$A13,"") | V13: =IF($Q13="Diganti/Dibuang",$A13,"") -> 8
A14: 9 | B14: =IF(KUNCI!B14="","",UPPER(KUNCI!B14)) -> D | C14: =IF($B14="","",SUM(SKOR!$M$6:$M$55)) -> 14 | D14: =IF($B14="","",N_SISWA-C14) -> 17 | E14: =IF($B14="","",IFERROR(C14/N_SISWA,"")) -> 0.4516129 | F14: =IF(E14="","",IF(E14<=BATAS_SUKAR,"Sukar",IF(E14<=BATAS_MUDAH,"Sedang","Mudah"))) -> Sedang | G14: =IF($B14="","",SUMIFS(SKOR!$M$6:$M$55,SKOR!$AW$6:$AW$55,"<="&N_GRUP)) -> 4 | H14: =IF($B14="","",SUMIFS(SKOR!$M$6:$M$55,SKOR!$AW$6:$AW$55,">"&(N_SISWA-N_GRUP))) -> 2 | I14: =IF($B14="","",IFERROR((G14-H14)/N_GRUP,"")) -> 0.25 | J14: =IF(I14="","",IF(I14<0,"Sangat jelek",IF(I14<=DP_B1,"Jelek",IF(I14<=DP_B2,"Cukup",IF(I14<=DP_B3,"Baik","Baik sekali"))))) -> Cukup | K14: =IF(OR($B14="",C14=0),"",SUMIFS(SKOR!$AS$6:$AS$55,SKOR!$M$6:$M$55,1)/C14) -> 25.5 | L14: =IF(K14="","",IFERROR((K14-MEAN_SKOR)/SD_SKOR*SQRT(E14/(1-E14)),"")) -> 0.24702493 | M14: =IF($B14="","",R_TABEL) -> 0.35504589 | N14: =IF($B14="","",IF(L14="","Tidak valid",IF(L14>M14,"Valid","Tidak valid"))) -> Tidak valid | O14: =IF($B14="","",E14*(1-E14)) -> 0.24765869 | P14: =IF($B14="","",PENGECOH!T14) -> 3 | Q14: =IF($B14="","",IF(AND(ISNUMBER(I14),I14<0),"Diganti/Dibuang",IF((N14="Valid")+AND(ISNUMBER(I14),I14>DP_B1)+(F14="Sedang")=3,"Diterima",IF((N14="Valid")+AND(ISNUMBER(I14),I14>DP_B1)+(F14="Sedang")=2,"Direvisi","Diganti/Dibuang")))) -> Direvisi | R14: =IF($B14="","",IF(AND(Q14="Diterima",P14=3),"Soal baik; dapat disimpan di bank soal",TRIM(IF(F14="Sukar","Terlalu sukar. ",IF(F14="Mudah","Terlalu mudah. ",""))&IF(N14<>"Valid","Validitas rendah. ","")&IF(AND(ISNUMBER(I14),I14<0),"Daya pembeda negatif (periksa kunci). ",IF(AND(ISNUMBER(I14),I14>DP_B1),"","Daya pembeda rendah. "))&IF(P14<3,"Ada pengecoh tidak berfungsi.","")))) -> Validitas rendah. | S14: =IF(KUNCI!C14="","",KUNCI!C14) | T14: =IF($Q14="Diterima",$A14,"") | U14: =IF($Q14="Direvisi",$A14,"") -> 9 | V14: =IF($Q14="Diganti/Dibuang",$A14,"")
